# Generated by Django 3.0.7 on 2020-06-23 15:18

import django.contrib.postgres.fields.citext
import django.core.validators
from django.db import migrations, models
import django.db.models.deletion


class Migration(migrations.Migration):

    dependencies = [
        ('core', '0002_auto_20200620_1839'),
    ]

    operations = [
        migrations.AlterModelOptions(
            name='humanuser',
            options={'verbose_name': 'user', 'verbose_name_plural': 'users'},
        ),
        migrations.AlterModelOptions(
            name='nickname',
            options={'ordering': ['nickname'], 'verbose_name': 'nickname', 'verbose_name_plural': 'nicknames'},
        ),
        migrations.AlterModelOptions(
            name='serviceaccount',
            options={'verbose_name': 'service account', 'verbose_name_plural': 'service accounts'},
        ),
        migrations.AlterField(
            model_name='nickname',
            name='nickname',
            field=django.contrib.postgres.fields.citext.CICharField(db_index=True, max_length=15, unique=True, validators=[django.core.validators.RegexValidator('^[A-Za-z0-9]{3,15}$', 'Only letters and numbers are allowed.', 'invalid')], verbose_name='nickname'),
        ),
        migrations.AlterField(
            model_name='nickname',
            name='user',
            field=models.ForeignKey(on_delete=django.db.models.deletion.CASCADE, to='core.HumanUser', verbose_name='user'),
        ),
        migrations.AlterField(
            model_name='user',
            name='username',
            field=django.contrib.postgres.fields.citext.CICharField(error_messages={'unique': 'A user with that username already exists.'}, max_length=15, unique=True, validators=[django.core.validators.RegexValidator('^[A-Za-z0-9]{3,15}$', 'Only letters and numbers are allowed.', 'invalid')]),
        ),
    ]
